// SPDX-License-Identifier: MIT
pragma solidity 0.8.5;

// 作业思考： 
//     管理员操作修改时：函数参数要传 管理员地址 ＋ 要操作的内容
//     虽然有合约有基础，但是每个合约都有自己的空间
//     msg.sender要确认清楚，尤其是在部署合约时
//     各个费用，比如view、error、require....
contract day4{
    // 抛出异常有三个：
    //     require(condition,"错误信息")，当 require 式异常发生时，EVM 使用 REVERT 操作码回滚交易，剩余未使用的 Gas 将返回给交易发起者
    //     assert(condition)：函数通常用来检查内部逻辑
    //     revert()/revert(string memory reason)/revert fun(ar1,arg2)：推荐使用revert语句，因为gas最少还支持带异常消息。

    // 错误之定义含参的话，solidit语法需要0.8.4以上
    error Teenager(address, uint8);  

    function test_require(uint256 age) public pure {
        require(age<256, "Age cannot be greater than 256");
    }

    //  本来是想不能大于10万
    function test_assert(uint8 salary) public pure {
        uint totalSalary = 10000;
        assert(totalSalary+salary < 100000);
    }

    // 小于18岁，不让玩游戏 
    function test_revert1(uint8 age)public pure {
        if (age<=18) revert();
    }

    // 小于18岁，不让玩游戏 
    function test_revert2(uint8 age)public pure{
        string memory reason = "If you are under 18,you are not allows to play games";
        if (age<=18) revert(reason);
    }

    // // revert语句抛出异常，他会抛出一个编码，但凡你有合约中有这个编码，gas会少很多
    function test_revert3(uint8 age)public view {
        if (age<=18) revert Teenager(msg.sender, age);
    }

    function test1_require(uint256 age) public pure returns(uint256) {
        require(age<256, "Age cannot be greater than 256");
        return age;
    }

}

contract try1{
    // try/catch用在捕获外部合约调用失败，让这段语句不抛出异常
    // try/catch 语法上就不支持调用内部合约，编写代码是就会报错
    // try/catch允许获得外部调用的返回值
    // try/catch调用外部合约，在 catch 语句可以捕获异常的错误提示，错误提示转换为bytes
    // this.method属于外部调用
    // require/assert/revert()属于抛出异常
    error Not_zero(string);
    error Less_than_256(string);

    event ErrorCaught(string); // 添加事件日志

    
    day4 public day;   

    constructor(){
        day = new day4();
    }
    
    function test_try(uint256 number) public {

        try day.test_require(number){
            // 调用外部合约成功，则执行者里面的代码
        }catch Error(string memory reason){
            emit ErrorCaught(reason);
            // revert Less_than_256(reason)  // catch中再次有 revert的话，虽然捕获的异常，但是还是会再次抛出异常，因为catch中有revert语句，
        }catch (bytes memory reason){
            // 调用外部合约失败，catch捕获异常，EVM不会报错，test_try函数结束后也不会报警，
            // 这里面因该写一些失败原因给前端,bytes要转为string类型
            emit ErrorCaught(string(reason));
            // revert Less_than_256(string(reason));  // 这里面只能接受 catch(bytes) ，但我们尝试返回error(string),所有上面加一个catch error{}
        }
    }

    function test1_try(uint256 number) public view {
        // 语法上，就不支持内部调用 
        // try method1(number){
        // } catch {

        // }

        // this.method()属于外部调用。通过 this 调用会生成一个真正的 EVM 调用（CALL 操作码），会产生独立的执行上下文，遵守外部调用的所有规则（包括 Gas 和错误传递）
        try this.method1(number){
        } catch {

        }
    }

    function test2_try(uint256 number) public{

        try day.test1_require(number) returns(uint256 age){
            // try 接受外部合约的返回值
            age = age + 0;
        } catch Error(string memory reason){ 
            // catch 语句可以捕获异常的错误提示，错误提示转换为bytes
            emit ErrorCaught(reason);
        } catch (bytes memory reason) {
            emit ErrorCaught(string(reason));
        }
    }

    function method1(uint256 number) public pure {
        if(number==0) revert Not_zero("Not allow zero");
    }

}

contract interface1{
    // 在部署派生合约时，父合约不会连带被部署，可以理解为，在编译时，
    //     编译器会把父合约的代码拷贝进派生合约。因此，不能在派生合约再次声明父合约中已经存在的状态变量。
    // 父合约的构造函数代码会先调用而后调用派生合约的构造函数。

}

